Workbook
Name CCasting: Construction!$G$14
Name CCement: Construction!$G$5
Name CCementBrick: Construction!$G$11
Name CFixing: Construction!$G$12
Name CFormwork: Construction!$G$13
Name CLabour12: Construction!$G$16
Name CLabour25: Construction!$G$15
Name CMortar: Construction!$G$17
Name Consumables: Inputs!$C$22
Name CorrugatedInstall: Inputs!$C$25
Name CorrugatedSupply: Inputs!$C$24
Name CPlain: Construction!$G$9
Name CPump: Construction!$G$8
Name CReadyMix: Construction!$G$7
Name CRebar: Construction!$G$4
Name CRedBrick: Construction!$G$10
Name CSand: Construction!$G$6
Name FabMetal: Inputs!$C$18
Name FabStructure: Inputs!$C$17
Name Materials: Inputs!$A$4:$C$14
Name Paint: Inputs!$C$19
Name SandwichInstall: Inputs!$C$27
Name SandwichSupply: Inputs!$C$26
Name Transport: Inputs!$C$23
Name WasteMetal: Inputs!$C$21
Name WasteStructure: Inputs!$C$20

Sheet Read me
A1: Price list - steel structures, metal works and construction works (Cairo, 2026)
A2: 1. Steel and metal works (SW, MW): unit price = material + waste + consumables + fabrication and erection + paint + transport. No overhead and no profit.
A3: 2. Their material prices are from the Ministry of Housing building materials price bulletin, August 2026 (including tax, excluding transport). The bulletin is in the sources folder.
A4: 3. Construction works (CW): Egyptian market rates, July 2026, delivered to site, reviewed by a practising engineer. The build-up is in the Construction sheet. 'Market adjustment' is the hand correction applied to the calculated price.
A5: 4. Yellow cells are estimates without a firm source. Please check them first.
A6: 5. Please write your own price or comment in the last two columns (green) of the Price list sheet.
A8: قائمة أسعار - منشآت معدنية وأعمال حدادة وأعمال إنشائية (القاهرة، 2026)
A9: 1. المنشآت المعدنية والحدادة (SW, MW): سعر الوحدة = الخامة + الهالك + المستهلكات + المصنعية والتركيب + الدهان + النقل. لا يشمل المصاريف الإدارية ولا الربح.
A10: 2. أسعار خاماتها من نشرة أسعار مواد البناء لوزارة الإسكان، أغسطس 2026 (شاملة الضرائب وغير شاملة النقل). النشرة موجودة في فولدر sources.
A11: 3. الأعمال الإنشائية (CW): أسعار السوق المصري، يوليو 2026، تسليم الموقع، مراجعة مهندس ممارس. تحليل السعر في شيت Construction، و'تعديل السوق' هو الفرق المضاف يدوياً على السعر المحسوب.
A12: 4. الخلايا الصفراء تقديرات بدون مصدر مؤكد، برجاء مراجعتها أولاً.
A13: 5. برجاء كتابة سعرك أو ملاحظتك في آخر عمودين (باللون الأخضر) في شيت Price list.

Sheet Price list
A1: Code | B1: Item (Arabic) | C1: Item (English) | D1: Unit | E1: Type | F1: Material | G1: kg per unit | H1: Material + waste | I1: Consumables | J1: Labour | K1: Paint | L1: Transport | M1: Cost per ton | N1: Direct cost per unit | O1: Unit price (EGP) | P1: Note | Q1: Your price (EGP) | R1: Your comment
A2: SW-01 | B2: توريد وتصنيع وتركيب ودهان منشآت معدنية من قطاعات ثقيلة | C2: Supply, fabricate, erect and paint steel structure, heavy sections | D2: ton / طن | E2: Structure | F2: Heavy beams UPN/IPN/HEA/HEB 14-40 cm | G2: 1000 | H2: =ROUND(VLOOKUP($F2,Materials,3,FALSE)*(1+IF($E2="Structure",WasteStructure,WasteMetal)),0) -> 60480 | I2: =ROUND(VLOOKUP($F2,Materials,3,FALSE)*Consumables,0) -> 1728 | J2: =IF($E2="Structure",FabStructure,FabMetal) -> 15000 | K2: =Paint -> 2500 | L2: =Transport -> 1200 | M2: =SUM(H2:L2) -> 80908 | O2: =ROUND(G2/1000*M2,0) -> 80908
A3: SW-02 | B3: توريد وتصنيع وتركيب ودهان منشآت معدنية من قطاعات متوسطة | C3: Supply, fabricate, erect and paint steel structure, medium sections | D3: ton / طن | E3: Structure | F3: Medium beams 8-12 cm | G3: 1000 | H3: =ROUND(VLOOKUP($F3,Materials,3,FALSE)*(1+IF($E3="Structure",WasteStructure,WasteMetal)),0) -> 53550 | I3: =ROUND(VLOOKUP($F3,Materials,3,FALSE)*Consumables,0) -> 1530 | J3: =IF($E3="Structure",FabStructure,FabMetal) -> 15000 | K3: =Paint -> 2500 | L3: =Transport -> 1200 | M3: =SUM(H3:L3) -> 73780 | O3: =ROUND(G3/1000*M3,0) -> 73780
A4: SW-03 | B4: هيكل جمالون معدني (بالمتر المربع من المساحة المغطاة) | C4: Steel shed frame, per m² of covered area | D4: m² / م² | E4: Structure | F4: Heavy beams UPN/IPN/HEA/HEB 14-40 cm | G4: 30 | H4: =ROUND(VLOOKUP($F4,Materials,3,FALSE)*(1+IF($E4="Structure",WasteStructure,WasteMetal)),0) -> 60480 | I4: =ROUND(VLOOKUP($F4,Materials,3,FALSE)*Consumables,0) -> 1728 | J4: =IF($E4="Structure",FabStructure,FabMetal) -> 15000 | K4: =Paint -> 2500 | L4: =Transport -> 1200 | M4: =SUM(H4:L4) -> 80908 | O4: =ROUND(G4/1000*M4,0) -> 2427 | P4: 30 kg/m² from Injaz range 25-35 kg/m²
A5: SW-04 | B5: ألواح القواعد والوصلات والتقويات | C5: Base plates, connection plates and stiffeners | D5: ton / طن | E5: Structure | F5: Steel plate 8-10 mm | G5: 1000 | H5: =ROUND(VLOOKUP($F5,Materials,3,FALSE)*(1+IF($E5="Structure",WasteStructure,WasteMetal)),0) -> 48300 | I5: =ROUND(VLOOKUP($F5,Materials,3,FALSE)*Consumables,0) -> 1380 | J5: =IF($E5="Structure",FabStructure,FabMetal) -> 15000 | K5: =Paint -> 2500 | L5: =Transport -> 1200 | M5: =SUM(H5:L5) -> 68380 | O5: =ROUND(G5/1000*M5,0) -> 68380
A6: SW-05 | B6: تغطية سقف بصاج مجلفن معرج 0.5 مم توريد وتركيب | C6: Roof cladding, corrugated galvanized sheet 0.5 mm, supply and install | D6: m² / م² | E6: Cladding | N6: =CorrugatedSupply+CorrugatedInstall -> 225 | O6: =N6 -> 225
A7: SW-06 | B7: تغطية سقف بألواح ساندوتش بانل توريد وتركيب | C7: Roof cladding, sandwich panel, supply and install | D7: m² / م² | E7: Cladding | N7: =SandwichSupply+SandwichInstall -> 700 | O7: =N7 -> 700
A8: MW-01 | B8: سلالم حديد (قطاعات وصاج) | C8: Steel stairs (sections and plate) | D8: ton / طن | E8: Metal works | F8: Medium beams 8-12 cm | G8: 1000 | H8: =ROUND(VLOOKUP($F8,Materials,3,FALSE)*(1+IF($E8="Structure",WasteStructure,WasteMetal)),0) -> 56100 | I8: =ROUND(VLOOKUP($F8,Materials,3,FALSE)*Consumables,0) -> 1530 | J8: =IF($E8="Structure",FabStructure,FabMetal) -> 30000 | K8: =Paint -> 2500 | L8: =Transport -> 1200 | M8: =SUM(H8:L8) -> 91330 | O8: =ROUND(G8/1000*M8,0) -> 91330
A9: MW-02 | B9: أرضيات ومنصات صاج بقلاوة | C9: Checker plate floors and platforms | D9: ton / طن | E9: Metal works | F9: Checker plate 3-10 mm | G9: 1000 | H9: =ROUND(VLOOKUP($F9,Materials,3,FALSE)*(1+IF($E9="Structure",WasteStructure,WasteMetal)),0) -> 57200 | I9: =ROUND(VLOOKUP($F9,Materials,3,FALSE)*Consumables,0) -> 1560 | J9: =IF($E9="Structure",FabStructure,FabMetal) -> 30000 | K9: =Paint -> 2500 | L9: =Transport -> 1200 | M9: =SUM(H9:L9) -> 92460 | O9: =ROUND(G9/1000*M9,0) -> 92460
A10: MW-03 | B10: درابزين حديد من المواسير المربعة | C10: Steel railing from square tubes | D10: m / م.ط | E10: Metal works | F10: Hollow sections (square/rect tubes) | G10: 15 | H10: =ROUND(VLOOKUP($F10,Materials,3,FALSE)*(1+IF($E10="Structure",WasteStructure,WasteMetal)),0) -> 51370 | I10: =ROUND(VLOOKUP($F10,Materials,3,FALSE)*Consumables,0) -> 1401 | J10: =IF($E10="Structure",FabStructure,FabMetal) -> 30000 | K10: =Paint -> 2500 | L10: =Transport -> 1200 | M10: =SUM(H10:L10) -> 86471 | O10: =ROUND(G10/1000*M10,0) -> 1297 | P10: Weight per unit is an estimate
A11: MW-04 | B11: باب حديد صاج بالحلق | C11: Steel sheet door with frame | D11: m² / م² | E11: Metal works | F11: Cold-rolled sheet | G11: 40 | H11: =ROUND(VLOOKUP($F11,Materials,3,FALSE)*(1+IF($E11="Structure",WasteStructure,WasteMetal)),0) -> 59400 | I11: =ROUND(VLOOKUP($F11,Materials,3,FALSE)*Consumables,0) -> 1620 | J11: =IF($E11="Structure",FabStructure,FabMetal) -> 30000 | K11: =Paint -> 2500 | L11: =Transport -> 1200 | M11: =SUM(H11:L11) -> 94720 | O11: =ROUND(G11/1000*M11,0) -> 3789 | P11: Weight per unit is an estimate
A12: MW-05 | B12: بوابة حديد من المواسير | C12: Steel gate from tubes | D12: m² / م² | E12: Metal works | F12: Hollow sections (square/rect tubes) | G12: 35 | H12: =ROUND(VLOOKUP($F12,Materials,3,FALSE)*(1+IF($E12="Structure",WasteStructure,WasteMetal)),0) -> 51370 | I12: =ROUND(VLOOKUP($F12,Materials,3,FALSE)*Consumables,0) -> 1401 | J12: =IF($E12="Structure",FabStructure,FabMetal) -> 30000 | K12: =Paint -> 2500 | L12: =Transport -> 1200 | M12: =SUM(H12:L12) -> 86471 | O12: =ROUND(G12/1000*M12,0) -> 3026 | P12: Weight per unit is an estimate
A13: MW-06 | B13: حماية شبابيك حديد | C13: Steel window guards | D13: m² / م² | E13: Metal works | F13: Flat bar 6 m | G13: 15 | H13: =ROUND(VLOOKUP($F13,Materials,3,FALSE)*(1+IF($E13="Structure",WasteStructure,WasteMetal)),0) -> 47300 | I13: =ROUND(VLOOKUP($F13,Materials,3,FALSE)*Consumables,0) -> 1290 | J13: =IF($E13="Structure",FabStructure,FabMetal) -> 30000 | K13: =Paint -> 2500 | L13: =Transport -> 1200 | M13: =SUM(H13:L13) -> 82290 | O13: =ROUND(G13/1000*M13,0) -> 1234 | P13: Weight per unit is an estimate
A14: MW-07 | B14: أعمال حدادة عامة وحديد كريتال توريد وتصنيع وتركيب ودهان | C14: General metal works and crittall steel: supply, fabricate, install and paint | D14: ton / طن | E14: Metal works | F14: Medium angles 60-100 mm | G14: 1000 | H14: =ROUND(VLOOKUP($F14,Materials,3,FALSE)*(1+IF($E14="Structure",WasteStructure,WasteMetal)),0) -> 52800 | I14: =ROUND(VLOOKUP($F14,Materials,3,FALSE)*Consumables,0) -> 1440 | J14: =IF($E14="Structure",FabStructure,FabMetal) -> 30000 | K14: =Paint -> 2500 | L14: =Transport -> 1200 | M14: =SUM(H14:L14) -> 87940 | O14: =ROUND(G14/1000*M14,0) -> 87940 | P14: New item (Sep 2026): built from existing rates - please check
A15: CW-01 | B15: أعمال الحفر مع نقل الناتج خارج الموقع | C15: Excavation with hauling away | D15: m³ / م³ | E15: Construction | N15: =Construction!$E$36 -> 130 | O15: =N15 -> 130 | P15: Egyptian market cost model, July 2026 (reviewed by a practising engineer)
A16: CW-02 | B16: توريد وفرد ودمك طبقة إحلال رمل وزلط | C16: Supply, spread and compact sand-gravel replacement layer | D16: m³ / م³ | E16: Construction | N16: =Construction!$E$37 -> 480 | O16: =N16 -> 480 | P16: Egyptian market cost model, July 2026 (reviewed by a practising engineer)
A17: CW-03 | B17: أعمال الردم والدمك حول حوائط البدروم | C17: Backfill and compaction around basement walls | D17: m³ / م³ | E17: Construction | N17: =Construction!$E$38 -> 120 | O17: =N17 -> 120 | P17: Egyptian market cost model, July 2026 (reviewed by a practising engineer)
A18: CW-04 | B18: خرسانة عادية فرشة نظافة سماكة 10 سم | C18: Plain concrete blinding 10 cm | D18: m³ / م³ | E18: Construction | N18: =Construction!$L$20 -> 3000 | O18: =N18 -> 3000 | P18: Egyptian market cost model, July 2026 (reviewed by a practising engineer)
A19: CW-05 | B19: خرسانة مسلحة للقواعد والسملات | C19: Reinforced concrete footings and tie beams | D19: m³ / م³ | E19: Construction | N19: =Construction!$L$21 -> 8100 | O19: =N19 -> 8100 | P19: Egyptian market cost model, July 2026 (reviewed by a practising engineer)
A20: CW-06 | B20: خرسانة مسلحة بلاطة أرضية على التربة 15 سم بطبقة حديد واحدة | C20: RC slab on grade 15 cm, one rebar layer | D20: m³ / م³ | E20: Construction | N20: =Construction!$L$22 -> 4500 | O20: =N20 -> 4500 | P20: Egyptian market cost model, July 2026 (reviewed by a practising engineer)
A21: CW-07 | B21: خرسانة مسلحة لحوائط البدروم الساندة | C21: RC basement retaining walls | D21: m³ / م³ | E21: Construction | N21: =Construction!$L$23 -> 9635 | O21: =N21 -> 9635 | P21: Egyptian market cost model, July 2026 (reviewed by a practising engineer)
A22: CW-08 | B22: خرسانة مسلحة للأعمدة ورقاب الأعمدة | C22: RC columns and column necks | D22: m³ / م³ | E22: Construction | N22: =Construction!$L$24 -> 12500 | O22: =N22 -> 12500 | P22: Egyptian market cost model, July 2026 (reviewed by a practising engineer)
A23: CW-09 | B23: خرسانة مسلحة للبلاطات فلات سلاب والكمرات الطرفية | C23: RC flat slabs and edge beams | D23: m³ / م³ | E23: Construction | N23: =Construction!$L$25 -> 9300 | O23: =N23 -> 9300 | P23: Egyptian market cost model, July 2026 (reviewed by a practising engineer)
A24: CW-10 | B24: خرسانة مسلحة للسلالم والبسطات | C24: RC stairs and landings | D24: m³ / م³ | E24: Construction | N24: =Construction!$L$26 -> 9500 | O24: =N24 -> 9500 | P24: Egyptian market cost model, July 2026 (reviewed by a practising engineer)
A25: CW-11 | B25: خرسانة مسلحة لحوائط بيت المصعد | C25: RC lift shaft walls | D25: m³ / م³ | E25: Construction | N25: =Construction!$L$27 -> 9550 | O25: =N25 -> 9550 | P25: Egyptian market cost model, July 2026 (reviewed by a practising engineer)
A26: CW-12 | B26: مباني طوب حوائط خارجية 25 سم (75% وردي + 25% أسمنتي) | C26: Brick external walls 25 cm (75% red, 25% cement brick) | D26: m² / م² | E26: Construction | N26: =Construction!$K$30 -> 600.125 | O26: =N26 -> 600.125 | P26: Egyptian market cost model, July 2026 (reviewed by a practising engineer)
A27: CW-13 | B27: مباني طوب قواطيع داخلية 12 سم (75% وردي + 25% أسمنتي) | C27: Brick partitions 12 cm (75% red, 25% cement brick) | D27: m² / م² | E27: Construction | N27: =Construction!$K$31 -> 320.9425 | O27: =N27 -> 320.9425 | P27: Egyptian market cost model, July 2026 (reviewed by a practising engineer)
A28: CW-14 | B28: مباني البدروم حوائط 25 سم - طوب أسمنتي | C28: Basement walls 25 cm, cement brick | D28: m² / م² | E28: Construction | N28: =Construction!$K$32 -> 1001 | O28: =N28 -> 1001 | P28: Egyptian market cost model, July 2026 (reviewed by a practising engineer)
A29: CW-15 | B29: مباني البدروم قواطيع 12 سم - طوب أسمنتي | C29: Basement partitions 12 cm, cement brick | D29: m² / م² | E29: Construction | N29: =Construction!$K$33 -> 500.08 | O29: =N29 -> 500.08 | P29: Egyptian market cost model, July 2026 (reviewed by a practising engineer)
A30: CW-16 | B30: عزل مائي ممبرين طبقتين + طبقة حماية | C30: Waterproofing, 2-layer bitumen membrane + protection layer | D30: m² / م² | E30: Construction | N30: =Construction!$E$39 -> 330 | O30: =N30 -> 330 | P30: Egyptian market cost model, July 2026 (reviewed by a practising engineer)
A31: CW-17 | B31: عزل حراري فوم أزرق + رمي أسطح | C31: Roof thermal insulation, blue foam + screed | D31: m² / م² | E31: Construction | N31: =Construction!$E$40 -> 350 | O31: =N31 -> 350 | P31: Egyptian market cost model, July 2026 (reviewed by a practising engineer)
A32: CW-18 | B32: تأسيس شبكات الكهرباء (مواسير وعلب ولوحات) بدون أسلاك، لكل م² مسطح | C32: Electrical rough-in (conduits, boxes, panels), no wires, per m² of floor | D32: m² / م² | E32: Construction | N32: =Construction!$E$41 -> 260 | O32: =N32 -> 260 | P32: Egyptian market cost model, July 2026 (reviewed by a practising engineer)
A33: CW-19 | B33: تأسيس شبكات السباكة والصرف مع اختبارات الضغط، لكل م² مسطح | C33: Plumbing and drainage rough-in with pressure tests, per m² of floor | D33: m² / م² | E33: Construction | N33: =Construction!$E$42 -> 250 | O33: =N33 -> 250 | P33: Egyptian market cost model, July 2026 (reviewed by a practising engineer)
A34: CW-20 | B34: المحارة الداخلية للحوائط والأسقف | C34: Internal plaster, walls and ceilings | D34: m² / م² | E34: Construction | N34: =Construction!$E$43 -> 185 | O34: =N34 -> 185 | P34: Egyptian market cost model, July 2026 (reviewed by a practising engineer)
A35: CW-21 | B35: المحارة الخارجية للواجهات شاملة السقالات | C35: External plaster including scaffolding | D35: m² / م² | E35: Construction | N35: =Construction!$E$44 -> 270 | O35: =N35 -> 270 | P35: Egyptian market cost model, July 2026 (reviewed by a practising engineer)
A36: CW-22 | B36: شبابيك ألومنيوم بزجاج مزدوج + أبواب البلكونات | C36: Aluminium windows, double glazed, including balcony doors | D36: m² / م² | E36: Construction | N36: =Construction!$E$45 -> 4200 | O36: =N36 -> 4200 | P36: Egyptian market cost model, July 2026 (reviewed by a practising engineer)
A37: CW-23 | B37: تشطيب الواجهات - دهان محاجر خارجي | C37: Facade finish, stone-effect paint | D37: m² / م² | E37: Construction | N37: =Construction!$E$46 -> 300 | O37: =N37 -> 300 | P37: Egyptian market cost model, July 2026 (reviewed by a practising engineer)
A38: CW-24 | B38: تشطيب الواجهات - تكسية حجر طبيعي | C38: Facade finish, natural stone cladding | D38: m² / م² | E38: Construction | N38: =Construction!$E$47 -> 2300 | O38: =N38 -> 2300 | P38: Egyptian market cost model, July 2026 (reviewed by a practising engineer)
A39: CW-25 | B39: مصعد كهربائي 6 توقفات شامل التركيب | C39: Electric elevator, 6 stops, including installation | D39: no. / عدد | E39: Construction | N39: =Construction!$E$48 -> 750000 | O39: =N39 -> 750000 | P39: Egyptian market cost model, July 2026 (reviewed by a practising engineer)
A40: CW-26 | B40: توريد وتقطيع وتشكيل وتركيب حديد التسليح | C40: Rebar, supply, cut, bend and fix | D40: ton / طن | E40: Construction | N40: =Construction!$E$49 -> 41000 | O40: =N40 -> 41000 | P40: New item (Sep 2026): rebar + fixing from the model's rates - please check

Sheet Inputs
A1: Cairo prices, including tax, excluding transport. Yellow = estimate, please check. No overhead or profit here.
A3: Material (English) | B3: Material (Arabic) | C3: EGP per ton | D3: Source | E3: PDF page
A4: Heavy beams UPN/IPN/HEA/HEB 14-40 cm | B4: كمر ثقيل UPN/IPN/HEB/HEA من 14 إلى 40 سم | C4: 57600 | D4: Ministry of Housing price bulletin, Aug 2026 | E4: 7
A5: Medium beams 8-12 cm | B5: كمر وسط 8، 10، 12 سم | C5: 51000 | D5: Ministry of Housing price bulletin, Aug 2026 | E5: 7
A6: Small channels 2-4 cm | B6: كمر سيجال من 2 إلى 4 سم | C6: 48000 | D6: Ministry of Housing price bulletin, Aug 2026 | E6: 7
A7: Heavy angles 120-200 mm | B7: زوايا ثقيلة من 120 إلى 200 مم | C7: 54000 | D7: Ministry of Housing price bulletin, Aug 2026 | E7: 7
A8: Medium angles 60-100 mm | B8: زوايا متوسطة من 60 إلى 100 مم | C8: 48000 | D8: Ministry of Housing price bulletin, Aug 2026 | E8: 8
A9: Light angles 40-50 mm | B9: زوايا خفيفة من 40 إلى 50 مم | C9: 45000 | D9: Ministry of Housing price bulletin, Aug 2026 | E9: 8
A10: Flat bar 6 m | B10: خوص طول 6 م | C10: 43000 | D10: Ministry of Housing price bulletin, Aug 2026 | E10: 8
A11: Cold-rolled sheet | B11: صاج على البارد | C11: 54000 | D11: Ministry of Housing price bulletin, Aug 2026 | E11: 8
A12: Steel plate 8-10 mm | B12: ألواح الصاج الصنوبر من 8 إلى 10 مم | C12: 46000 | D12: Ministry of Housing price bulletin, Aug 2026 | E12: 134
A13: Checker plate 3-10 mm | B13: ألواح الصاج البقلاوة من 3 إلى 10 مم | C13: 52000 | D13: Ministry of Housing price bulletin, Aug 2026 | E13: 134
A14: Hollow sections (square/rect tubes) | B14: مواسير مربعة ومستطيلة (علب) | C14: 46700 | D14: Not in the bulletin. El Kayan Steel and GTCO price guides 2026: 46,000-46,700 ex-works
A16: Rate (English) | B16: Rate (Arabic) | C16: Value | D16: Source | E16: Unit
A17: Steel structures: fabricate + erect | B17: منشآت معدنية: مصنعية وتركيب | C17: 15000 | D17: Injaz (steel contractor site), 2026 | E17: EGP/ton
A18: Metal works (railings, doors, gates, stairs): fabricate + install | B18: أعمال حدادة: مصنعية وتركيب | C18: 30000 | D18: Estimate - please check | E18: EGP/ton
A19: Painting: primer + 2 coats | B19: دهان: طبقة أساس + طبقتين | C19: 2500 | D19: Estimate - please check | E19: EGP/ton
A20: Waste, steel structures | B20: هالك منشآت معدنية | C20: 0.05 | D20: Estimate - please check | E20: %
A21: Waste, metal works | B21: هالك أعمال حدادة | C21: 0.1 | D21: Estimate - please check | E21: %
A22: Welding wire, discs, gas, bolts (share of material cost) | B22: مستهلكات: سلك لحام، صواريخ، غاز، مسامير | C22: 0.03 | D22: Estimate - please check | E22: %
A23: Transport to site | B23: نقل للموقع | C23: 1200 | D23: Egyptian market cost model, July 2026: steel transport to site | E23: EGP/ton
A24: Corrugated galvanized sheet 0.5 mm, supply | B24: صاج مجلفن معرج 0.5 مم، توريد | C24: 200 | D24: Injaz 2026 range 150-320. Value chosen inside the range - please check | E24: EGP/m²
A25: Corrugated sheet, install | B25: صاج معرج، تركيب | C25: 25 | D25: Injaz (steel contractor site), 2026 | E25: EGP/m²
A26: Sandwich panel, supply | B26: ساندوتش بانل، توريد | C26: 650 | D26: Injaz 2026 range 650-950. Value chosen inside the range - please check | E26: EGP/m²
A27: Sandwich panel, install | B27: ساندوتش بانل، تركيب | C27: 50 | D27: Injaz (steel contractor site), 2026 | E27: EGP/m²

Sheet Construction
A1: Egyptian market cost model, July 2026, reviewed by a practising engineer. Prices delivered to site. Unit price = calculated price + market adjustment (hand correction).
A3: Name | B3: Item (English) | C3: Item (Arabic) | D3: Unit | E3: Supplier price | F3: Transport to site | G3: Delivered price | H3: Note
A4: CRebar | B4: Rebar (investment grade) | C4: حديد التسليح (استثماري) | D4: ton / طن | E4: 36800 | F4: 1200 | G4: =E4+F4 -> 38000
A5: CCement | B5: Grey cement | C5: الأسمنت الرمادي | D5: ton / طن | E5: 4100 | F5: 300 | G5: =E5+F5 -> 4400
A6: CSand | B6: Washed sand | C6: رمل غسيل | D6: m³ / م³ | E6: 150 | F6: 150 | G6: =E6+F6 -> 300
A7: CReadyMix | B7: Ready-mix concrete, reinforced grade, delivered | C7: خرسانة جاهزة مسلحة توريد وتوصيل | D7: m³ / م³ | E7: 3000 | F7: 0 | G7: =E7+F7 -> 3000
A8: CPump | B8: Concrete pumping | C8: ضخ الخرسانة | D8: m³ / م³ | E8: 200 | F8: 0 | G8: =E8+F8 -> 200
A9: CPlain | B9: Plain concrete (blinding) | C9: خرسانة عادية (فرشة نظافة) | D9: m³ / م³ | E9: 2600 | F9: 0 | G9: =E9+F9 -> 2600
A10: CRedBrick | B10: Red brick 25x12x6 | C10: طوب وردي 25×12×6 | D10: 1000 bricks / ألف طوبة | E10: 2200 | F10: 250 | G10: =E10+F10 -> 2450
A11: CCementBrick | B11: Solid cement brick 25x12x6 | C11: طوب أسمنتي مصمت 25×12×6 | D11: 1000 bricks / ألف طوبة | E11: 3800 | F11: 200 | G11: =E11+F11 -> 4000 | H11: Source note says 1,400-1,800 per 1000 but the model used 3,800 - please check
A12: CFixing | B12: Rebar cutting and fixing labour | C12: مصنعية تقطيع وتركيب الحديد | D12: ton / طن | E12: 3000 | F12: 0 | G12: =E12+F12 -> 3000
A13: CFormwork | B13: Timber formwork, per m² of contact | C13: الشدة الخشبية لكل م² تلامس | D13: m² / م² | E13: 250 | F13: 0 | G13: =E13+F13 -> 250
A14: CCasting | B14: Casting and curing labour | C14: مصنعية الصب والمعالجة | D14: m³ / م³ | E14: 250 | F14: 0 | G14: =E14+F14 -> 250
A15: CLabour25 | B15: Bricklaying labour, 25 cm wall | C15: مصنعية مباني حائط 25 سم | D15: m² / م² | E15: 200 | F15: 0 | G15: =E15+F15 -> 200
A16: CLabour12 | B16: Bricklaying labour, 12 cm wall | C16: مصنعية مباني حائط 12 سم | D16: m² / م² | E16: 110 | F16: 0 | G16: =E16+F16 -> 110
A17: CMortar | B17: Cement mortar 1:5, per m³ (0.3 t cement + 1 m³ sand) | C17: مونة أسمنتية 1:5 لكل م³ | D17: m³ / م³ | G17: =0.3*CCement+1*CSand -> 1620
A19: Code | B19: Concrete item (English) | C19: Concrete item (Arabic) | D19: Rebar kg/m³ | E19: Formwork m²/m³ | F19: Concrete + pump | G19: Rebar + fixing | H19: Formwork | I19: Casting | J19: Calculated price | K19: Market adjustment | L19: Unit price per m³
A20: CW-04 | B20: Plain concrete blinding 10 cm | C20: خرسانة عادية فرشة نظافة سماكة 10 سم | D20: 0 | E20: 0.5 | F20: =CPlain -> 2600 | G20: =D20*(CRebar+CFixing)/1000 -> 0 | H20: =E20*CFormwork -> 125 | I20: =CCasting -> 250 | J20: =SUM(F20:I20) -> 2975 | K20: 25 | L20: =J20+K20 -> 3000
A21: CW-05 | B21: Reinforced concrete footings and tie beams | C21: خرسانة مسلحة للقواعد والسملات | D21: 100 | E21: 1 | F21: =CReadyMix+CPump -> 3200 | G21: =D21*(CRebar+CFixing)/1000 -> 4100 | H21: =E21*CFormwork -> 250 | I21: =CCasting -> 250 | J21: =SUM(F21:I21) -> 7800 | K21: 300 | L21: =J21+K21 -> 8100
A22: CW-06 | B22: RC slab on grade 15 cm, one rebar layer | C22: خرسانة مسلحة بلاطة أرضية على التربة 15 سم بطبقة حديد واحدة | D22: 50 | E22: 0.3 | F22: =CReadyMix+CPump -> 3200 | G22: =D22*(CRebar+CFixing)/1000 -> 2050 | H22: =E22*CFormwork -> 75 | I22: =CCasting -> 250 | J22: =SUM(F22:I22) -> 5575 | K22: -1075 | L22: =J22+K22 -> 4500
A23: CW-07 | B23: RC basement retaining walls | C23: خرسانة مسلحة لحوائط البدروم الساندة | D23: 110 | E23: 6.7 | F23: =CReadyMix+CPump -> 3200 | G23: =D23*(CRebar+CFixing)/1000 -> 4510 | H23: =E23*CFormwork -> 1675 | I23: =CCasting -> 250 | J23: =SUM(F23:I23) -> 9635 | K23: 0 | L23: =J23+K23 -> 9635
A24: CW-08 | B24: RC columns and column necks | C24: خرسانة مسلحة للأعمدة ورقاب الأعمدة | D24: 170 | E24: 11 | F24: =CReadyMix+CPump -> 3200 | G24: =D24*(CRebar+CFixing)/1000 -> 6970 | H24: =E24*CFormwork -> 2750 | I24: =CCasting -> 250 | J24: =SUM(F24:I24) -> 13170 | K24: -670 | L24: =J24+K24 -> 12500
A25: CW-09 | B25: RC flat slabs and edge beams | C25: خرسانة مسلحة للبلاطات فلات سلاب والكمرات الطرفية | D25: 130 | E25: 4.5 | F25: =CReadyMix+CPump -> 3200 | G25: =D25*(CRebar+CFixing)/1000 -> 5330 | H25: =E25*CFormwork -> 1125 | I25: =CCasting -> 250 | J25: =SUM(F25:I25) -> 9905 | K25: -605 | L25: =J25+K25 -> 9300
A26: CW-10 | B26: RC stairs and landings | C26: خرسانة مسلحة للسلالم والبسطات | D26: 110 | E26: 5 | F26: =CReadyMix+CPump -> 3200 | G26: =D26*(CRebar+CFixing)/1000 -> 4510 | H26: =E26*CFormwork -> 1250 | I26: =CCasting -> 250 | J26: =SUM(F26:I26) -> 9210 | K26: 290 | L26: =J26+K26 -> 9500
A27: CW-11 | B27: RC lift shaft walls | C27: خرسانة مسلحة لحوائط بيت المصعد | D27: 100 | E27: 10 | F27: =CReadyMix+CPump -> 3200 | G27: =D27*(CRebar+CFixing)/1000 -> 4100 | H27: =E27*CFormwork -> 2500 | I27: =CCasting -> 250 | J27: =SUM(F27:I27) -> 10050 | K27: -500 | L27: =J27+K27 -> 9550
A29: Code | B29: Wall item (English) | C29: Wall item (Arabic) | D29: Bricks per m² | E29: Red brick share | F29: Brick cost | G29: Mortar | H29: Labour | I29: Calculated price | J29: Market adjustment | K29: Unit price per m²
A30: CW-12 | B30: Brick external walls 25 cm (75% red, 25% cement brick) | C30: مباني طوب حوائط خارجية 25 سم (75% وردي + 25% أسمنتي) | D30: 110 | E30: 0.75 | F30: =D30*(E30*CRedBrick+(1-E30)*CCementBrick)/1000 -> 312.125 | G30: =0.05*CMortar -> 81 | H30: =CLabour25 -> 200 | I30: =SUM(F30:H30) -> 593.125 | J30: 7 | K30: =I30+J30 -> 600.125
A31: CW-13 | B31: Brick partitions 12 cm (75% red, 25% cement brick) | C31: مباني طوب قواطيع داخلية 12 سم (75% وردي + 25% أسمنتي) | D31: 55 | E31: 0.75 | F31: =D31*(E31*CRedBrick+(1-E31)*CCementBrick)/1000 -> 156.0625 | G31: =0.024*CMortar -> 38.88 | H31: =CLabour12 -> 110 | I31: =SUM(F31:H31) -> 304.9425 | J31: 16 | K31: =I31+J31 -> 320.9425
A32: CW-14 | B32: Basement walls 25 cm, cement brick | C32: مباني البدروم حوائط 25 سم - طوب أسمنتي | D32: 110 | E32: 0 | F32: =D32*(E32*CRedBrick+(1-E32)*CCementBrick)/1000 -> 440 | G32: =0.05*CMortar -> 81 | H32: =CLabour25 -> 200 | I32: =SUM(F32:H32) -> 721 | J32: 280 | K32: =I32+J32 -> 1001
A33: CW-15 | B33: Basement partitions 12 cm, cement brick | C33: مباني البدروم قواطيع 12 سم - طوب أسمنتي | D33: 55 | E33: 0 | F33: =D33*(E33*CRedBrick+(1-E33)*CCementBrick)/1000 -> 220 | G33: =0.024*CMortar -> 38.88 | H33: =CLabour12 -> 110 | I33: =SUM(F33:H33) -> 368.88 | J33: 131.2 | K33: =I33+J33 -> 500.08
A35: Code | B35: Item (English) | C35: Item (Arabic) | D35: Unit | E35: Unit price
A36: CW-01 | B36: Excavation with hauling away | C36: أعمال الحفر مع نقل الناتج خارج الموقع | D36: m³ / م³ | E36: 130
A37: CW-02 | B37: Supply, spread and compact sand-gravel replacement layer | C37: توريد وفرد ودمك طبقة إحلال رمل وزلط | D37: m³ / م³ | E37: 480
A38: CW-03 | B38: Backfill and compaction around basement walls | C38: أعمال الردم والدمك حول حوائط البدروم | D38: m³ / م³ | E38: 120
A39: CW-16 | B39: Waterproofing, 2-layer bitumen membrane + protection layer | C39: عزل مائي ممبرين طبقتين + طبقة حماية | D39: m² / م² | E39: 330
A40: CW-17 | B40: Roof thermal insulation, blue foam + screed | C40: عزل حراري فوم أزرق + رمي أسطح | D40: m² / م² | E40: 350
A41: CW-18 | B41: Electrical rough-in (conduits, boxes, panels), no wires, per m² of floor | C41: تأسيس شبكات الكهرباء (مواسير وعلب ولوحات) بدون أسلاك، لكل م² مسطح | D41: m² / م² | E41: 260
A42: CW-19 | B42: Plumbing and drainage rough-in with pressure tests, per m² of floor | C42: تأسيس شبكات السباكة والصرف مع اختبارات الضغط، لكل م² مسطح | D42: m² / م² | E42: 250
A43: CW-20 | B43: Internal plaster, walls and ceilings | C43: المحارة الداخلية للحوائط والأسقف | D43: m² / م² | E43: 185
A44: CW-21 | B44: External plaster including scaffolding | C44: المحارة الخارجية للواجهات شاملة السقالات | D44: m² / م² | E44: 270
...
